<?xml version="1.0" ?>
<mujoco model="ur3">
  <compiler angle="radian" meshdir="ur3/visual/"/>

  <asset>
    <mesh name="base" file="base.stl"/>
    <mesh name="shoulder" file="shoulder.stl"/>
    <mesh name="upperarm" file="upperarm.stl"/>
    <mesh name="forearm" file="forearm.stl"/>
    <mesh name="wrist1" file="wrist1.stl"/>
    <mesh name="wrist2" file="wrist2.stl"/>
    <mesh name="wrist3" file="wrist3.stl"/>
  </asset>

  <worldbody>
    
    <body name="base_link">
      <inertial pos="0 0 0" quat="0.5 0.5 -0.5 0.5" mass="2" diaginertia="4.41563 4.41305 4.41305"/>
      <geom type="mesh" contype="0" conaffinity="0" group="1" density="0" rgba="0.7 0.7 0.7 1" mesh="base"/>
      <geom type="mesh" rgba="0.7 0.7 0.7 1" mesh="base"/>
      <body name="shoulder_link" pos="0 0 0.1519">
        <inertial pos="0 0 0" mass="2" diaginertia="0.303093 0.303093 0.300625"/>
        
        <joint name="shoulder_pan_joint" pos="0 0 0" axis="0 0 1" range="-6.28319 6.28319" actuatorfrcrange="-330 330"/>
        
        <!-- <sensor>
            <jointpos joint="shoulder_pan_joint"/>
        </sensor> -->
        
        <geom type="mesh" contype="0" conaffinity="0" group="1" density="0" rgba="0.7 0.7 0.7 1" mesh="shoulder"/>
        <geom type="mesh" rgba="0.7 0.7 0.7 1" mesh="shoulder"/>
        <body name="upper_arm_link" pos="0 0.1198 0" quat="0.707107 0 0.707107 0">
          <inertial pos="0 0 0.121825" mass="3.42" diaginertia="0.316728 0.316728 0.304619"/>
          
          <joint name="shoulder_lift_joint" pos="0 0 0" axis="0 1 0" range="-6.28319 6.28319" actuatorfrcrange="-330 330"/>
          
          <!-- <sensor>
              <jointpos joint="shoulder_lift_joint"/>
          </sensor> -->
                    
          <geom type="mesh" contype="0" conaffinity="0" group="1" density="0" rgba="0.7 0.7 0.7 1" mesh="upperarm"/>
          <geom type="mesh" rgba="0.7 0.7 0.7 1" mesh="upperarm"/>
          <body name="forearm_link" pos="0 -0.0925 0.24365">
            <inertial pos="0 0 0.106625" mass="1.26" diaginertia="0.0375468 0.0375468 0.0345437"/>
            
            <joint name="elbow_joint" pos="0 0 0" axis="0 1 0" range="-3.14159 3.14159" actuatorfrcrange="-150 150"/>
            
            <!-- <sensor>
                <jointpos joint="elbow_joint"/>
            </sensor> -->

            <geom type="mesh" contype="0" conaffinity="0" group="1" density="0" rgba="0.7 0.7 0.7 1" mesh="forearm"/>
            <geom type="mesh" rgba="0.7 0.7 0.7 1" mesh="forearm"/>
            <body name="wrist_1_link" pos="0 0 0.21325" quat="0.707107 0 0.707107 0">
              <inertial pos="0 0 0" quat="0.5 0.5 -0.5 0.5" mass="0.8" diaginertia="0.03325 0.033085 0.033085"/>
              
              <joint name="wrist_1_joint" pos="0 0 0" axis="0 1 0" range="-6.28319 6.28319" actuatorfrcrange="-54 54"/>
              
              <!-- <sensor>
                  <jointpos joint="wrist_1_joint"/>
              </sensor> -->

              <geom type="mesh" contype="0" conaffinity="0" group="1" density="0" rgba="0.7 0.7 0.7 1" mesh="wrist1"/>
              <geom type="mesh" rgba="0.7 0.7 0.7 1" mesh="wrist1"/>
              <body name="wrist_2_link" pos="0 0.08505 0">
                <inertial pos="0 0 0" quat="0.5 0.5 -0.5 0.5" mass="0.8" diaginertia="0.03325 0.033085 0.033085"/>
                
                <joint name="wrist_2_joint" pos="0 0 0" axis="0 0 1" range="-6.28319 6.28319" actuatorfrcrange="-54 54"/>
                
                <!-- <sensor>
                    <jointpos joint="wrist_2_joint"/>
                </sensor> -->

                <geom type="mesh" contype="0" conaffinity="0" group="1" density="0" rgba="0.7 0.7 0.7 1" mesh="wrist2"/>
                <geom type="mesh" rgba="0.7 0.7 0.7 1" mesh="wrist2"/>
                <body name="wrist_3_link" pos="0 0 0.08535">
                  <inertial pos="0 0 0" quat="0.5 0.5 -0.5 0.5" mass="0.35" diaginertia="0.0319844 0.0319122 0.0319122"/>
                  
                  <joint name="wrist_3_joint" pos="0 0 0" axis="0 1 0" range="-6.28319 6.28319" actuatorfrcrange="-54 54"/>
                  
                  <!-- <sensor>
                      <jointpos joint="wrist_3_joint"/>
                  </sensor> -->

                  <geom type="mesh" contype="0" conaffinity="0" group="1" density="0" rgba="0.7 0.7 0.7 1" mesh="wrist3"/>
                  <geom type="mesh" rgba="0.7 0.7 0.7 1" mesh="wrist3"/>
                  <body name="ee_link" pos="0 0.0819 0" quat="0.707107 0 0 0.707107">
                    <geom size="0.005 0.005 0.005" pos="-0.01 0 0" type="box"/>
                  </body>
                  <body name="tool0" pos="0 0.0819 0" quat="0.707107 -0.707107 0 0"/>
                </body>
              </body>
            </body>
          </body>
        </body>
      </body>
      <body name="base" quat="0 0 0 -1"/>
    </body>
  </worldbody>

  <actuator>
      <!-- Shoulder Pan Joint -->
    <motor name="shoulder_pitch_motor" joint="shoulder_pan_joint" gear="100" 
          ctrlrange="-6.28319 6.28319" ctrllimited="true" 
          forcerange="-1000 1000" forcelimited="true"/>

    <!-- Shoulder Lift Joint -->
    <motor name="shoulder_lift_motor" joint="shoulder_lift_joint" gear="100" 
          ctrlrange="-6.28319 6.28319" ctrllimited="true" 
          forcerange="-1000 1000" forcelimited="true"/>

    <!-- Elbow Joint -->
    <motor name="elbow_motor" joint="elbow_joint" gear="60" 
          ctrlrange="-3.14159 3.14159" ctrllimited="true" 
          forcerange="-600 600" forcelimited="true"/>

    <!-- Wrist 1 Joint -->
    <motor name="wrist1_motor" joint="wrist_1_joint" gear="36" 
          ctrlrange="-6.28319 6.28319" ctrllimited="true" 
          forcerange="-360 360" forcelimited="true"/>

    <!-- Wrist 2 Joint -->
    <motor name="wrist2_motor" joint="wrist_2_joint" gear="36" 
          ctrlrange="-6.28319 6.28319" ctrllimited="true" 
          forcerange="-360 360" forcelimited="true"/>

    <!-- Wrist 3 Joint -->
    <motor name="wrist3_motor" joint="wrist_3_joint" gear="36" 
          ctrlrange="-6.28319 6.28319" ctrllimited="true" 
          forcerange="-360 360" forcelimited="true"/>
  </actuator>

</mujoco>
